Workbook

Sheet Resumen
A1: Plan de Pruebas Manuales — TaskFlow
A2: Generado el 2026-09-22 — trazado a docs/PRD-TaskFlow-Completo.md y docs/analisis-diseño.md
A4: Total de casos | B4: Pendientes | C4: Aprobados | D4: Fallidos | E4: Bloqueados | F4: % completado
A5: =COUNTA('Casos de Prueba'!A5:A9999) | B5: =COUNTIF('Casos de Prueba'!L:L,"Pendiente") | C5: =COUNTIF('Casos de Prueba'!L:L,"Aprobado") | D5: =COUNTIF('Casos de Prueba'!L:L,"Fallido") | E5: =COUNTIF('Casos de Prueba'!L:L,"Bloqueado") | F5: =(C5+D5)/A5
A7: Conteo por módulo
A8: Módulo | B8: Nº casos | C8: Aprobados | D8: Fallidos | E8: Pendientes | F8: Bloqueados
A9: Gestión de tareas — Crear | B9: =COUNTIF('Casos de Prueba'!B:B,"Gestión de tareas — Crear") | C9: =COUNTIFS('Casos de Prueba'!B:B,"Gestión de tareas — Crear",'Casos de Prueba'!L:L,"Aprobado") | D9: =COUNTIFS('Casos de Prueba'!B:B,"Gestión de tareas — Crear",'Casos de Prueba'!L:L,"Fallido") | E9: =COUNTIFS('Casos de Prueba'!B:B,"Gestión de tareas — Crear",'Casos de Prueba'!L:L,"Pendiente") | F9: =COUNTIFS('Casos de Prueba'!B:B,"Gestión de tareas — Crear",'Casos de Prueba'!L:L,"Bloqueado")
A10: Gestión de tareas — Editar | B10: =COUNTIF('Casos de Prueba'!B:B,"Gestión de tareas — Editar") | C10: =COUNTIFS('Casos de Prueba'!B:B,"Gestión de tareas — Editar",'Casos de Prueba'!L:L,"Aprobado") | D10: =COUNTIFS('Casos de Prueba'!B:B,"Gestión de tareas — Editar",'Casos de Prueba'!L:L,"Fallido") | E10: =COUNTIFS('Casos de Prueba'!B:B,"Gestión de tareas — Editar",'Casos de Prueba'!L:L,"Pendiente") | F10: =COUNTIFS('Casos de Prueba'!B:B,"Gestión de tareas — Editar",'Casos de Prueba'!L:L,"Bloqueado")
A11: Gestión de tareas — Completar y reabrir | B11: =COUNTIF('Casos de Prueba'!B:B,"Gestión de tareas — Completar y reabrir") | C11: =COUNTIFS('Casos de Prueba'!B:B,"Gestión de tareas — Completar y reabrir",'Casos de Prueba'!L:L,"Aprobado") | D11: =COUNTIFS('Casos de Prueba'!B:B,"Gestión de tareas — Completar y reabrir",'Casos de Prueba'!L:L,"Fallido") | E11: =COUNTIFS('Casos de Prueba'!B:B,"Gestión de tareas — Completar y reabrir",'Casos de Prueba'!L:L,"Pendiente") | F11: =COUNTIFS('Casos de Prueba'!B:B,"Gestión de tareas — Completar y reabrir",'Casos de Prueba'!L:L,"Bloqueado")
A12: Gestión de tareas — Eliminar | B12: =COUNTIF('Casos de Prueba'!B:B,"Gestión de tareas — Eliminar") | C12: =COUNTIFS('Casos de Prueba'!B:B,"Gestión de tareas — Eliminar",'Casos de Prueba'!L:L,"Aprobado") | D12: =COUNTIFS('Casos de Prueba'!B:B,"Gestión de tareas — Eliminar",'Casos de Prueba'!L:L,"Fallido") | E12: =COUNTIFS('Casos de Prueba'!B:B,"Gestión de tareas — Eliminar",'Casos de Prueba'!L:L,"Pendiente") | F12: =COUNTIFS('Casos de Prueba'!B:B,"Gestión de tareas — Eliminar",'Casos de Prueba'!L:L,"Bloqueado")
A13: Organización — Prioridad, categoría y vencimiento | B13: =COUNTIF('Casos de Prueba'!B:B,"Organización — Prioridad, categoría y vencimiento") | C13: =COUNTIFS('Casos de Prueba'!B:B,"Organización — Prioridad, categoría y vencimiento",'Casos de Prueba'!L:L,"Aprobado") | D13: =COUNTIFS('Casos de Prueba'!B:B,"Organización — Prioridad, categoría y vencimiento",'Casos de Prueba'!L:L,"Fallido") | E13: =COUNTIFS('Casos de Prueba'!B:B,"Organización — Prioridad, categoría y vencimiento",'Casos de Prueba'!L:L,"Pendiente") | F13: =COUNTIFS('Casos de Prueba'!B:B,"Organización — Prioridad, categoría y vencimiento",'Casos de Prueba'!L:L,"Bloqueado")
A14: Búsqueda y filtros | B14: =COUNTIF('Casos de Prueba'!B:B,"Búsqueda y filtros") | C14: =COUNTIFS('Casos de Prueba'!B:B,"Búsqueda y filtros",'Casos de Prueba'!L:L,"Aprobado") | D14: =COUNTIFS('Casos de Prueba'!B:B,"Búsqueda y filtros",'Casos de Prueba'!L:L,"Fallido") | E14: =COUNTIFS('Casos de Prueba'!B:B,"Búsqueda y filtros",'Casos de Prueba'!L:L,"Pendiente") | F14: =COUNTIFS('Casos de Prueba'!B:B,"Búsqueda y filtros",'Casos de Prueba'!L:L,"Bloqueado")
A15: Usuarios — Catálogo y asignación | B15: =COUNTIF('Casos de Prueba'!B:B,"Usuarios — Catálogo y asignación") | C15: =COUNTIFS('Casos de Prueba'!B:B,"Usuarios — Catálogo y asignación",'Casos de Prueba'!L:L,"Aprobado") | D15: =COUNTIFS('Casos de Prueba'!B:B,"Usuarios — Catálogo y asignación",'Casos de Prueba'!L:L,"Fallido") | E15: =COUNTIFS('Casos de Prueba'!B:B,"Usuarios — Catálogo y asignación",'Casos de Prueba'!L:L,"Pendiente") | F15: =COUNTIFS('Casos de Prueba'!B:B,"Usuarios — Catálogo y asignación",'Casos de Prueba'!L:L,"Bloqueado")
A16: Transversal — UX y accesibilidad | B16: =COUNTIF('Casos de Prueba'!B:B,"Transversal — UX y accesibilidad") | C16: =COUNTIFS('Casos de Prueba'!B:B,"Transversal — UX y accesibilidad",'Casos de Prueba'!L:L,"Aprobado") | D16: =COUNTIFS('Casos de Prueba'!B:B,"Transversal — UX y accesibilidad",'Casos de Prueba'!L:L,"Fallido") | E16: =COUNTIFS('Casos de Prueba'!B:B,"Transversal — UX y accesibilidad",'Casos de Prueba'!L:L,"Pendiente") | F16: =COUNTIFS('Casos de Prueba'!B:B,"Transversal — UX y accesibilidad",'Casos de Prueba'!L:L,"Bloqueado")
A18: Estado — Pendiente: gris | Aprobado: verde | Fallido: rojo | Bloqueado: naranja | No aplica: gris claro. Prioridad — Alta: rojo | Media: naranja | Baja: gris. Cada caso ocupa una fila por paso; las columnas de caso (ID, módulo, prioridad, tipo, estado...) están fusionadas verticalmente.

Sheet Casos de Prueba
A1: Plan de Pruebas Manuales — TaskFlow
A2: Cada conjunto de pruebas ocupa una fila por paso. Marcar el Estado (una vez por caso) tras ejecutar todos sus pasos: Pendiente, Aprobado, Fallido, Bloqueado o No aplica.
A4: ID Caso | B4: Módulo | C4: Historia / Requisito | D4: Escenario | E4: Precondiciones | F4: Nº Paso | G4: Acción | H4: Datos de prueba | I4: Resultado esperado | J4: Prioridad | K4: Tipo | L4: Estado | M4: Observaciones | N4: Probado por | O4: Fecha
A5: Gestión de tareas — Crear
A6: TC-GDTC-001 | B6: Gestión de tareas — Crear | C6: HU-001 / RF-001 | D6: Crear tarea solo con título obligatorio | E6: La aplicación está abierta con la lista de tareas visible. | F6: 1 | G6: Abrir el formulario de nueva tarea. | H6: — | I6: El formulario se muestra con el campo título vacío, listo para escribir. | J6: Alta | K6: Funcional | L6: Pendiente
F7: 2 | G7: Escribir el título sin rellenar el resto de campos. | H7: Título: 'Revisar informe mensual' | I7: El campo título muestra el texto introducido; el formulario permite guardar sin el resto de campos.
F8: 3 | G8: Guardar la tarea. | H8: — | I8: La tarea se crea, aparece inmediatamente en la lista sin recargar la página y sigue presente tras refrescar (persistida en SQLite).
A9: TC-GDTC-002 | B9: Gestión de tareas — Crear | C9: HU-001 / RF-001 | D9: Crear tarea con todos los campos | E9: La aplicación está abierta con la lista de tareas visible. | F9: 1 | G9: Abrir el formulario de nueva tarea. | H9: — | I9: El formulario muestra todos los campos disponibles: título, descripción, prioridad, categoría, vencimiento y usuario asignado. | J9: Alta | K9: Funcional | L9: Pendiente
F10: 2 | G10: Rellenar título, descripción, prioridad, categoría, fecha de vencimiento y usuario asignado. | H10: Título: 'Preparar demo'; Prioridad: Alta; Categoría: 'Formación'; Vencimiento: fecha futura; Asignado: usuario existente | I10: Todos los campos aceptan y muestran los valores introducidos sin errores de validación.
F11: 3 | G11: Guardar la tarea. | H11: — | I11: La tarea se crea y aparece en la lista con las etiquetas visibles de prioridad, categoría, vencimiento y usuario asignado.
A12: TC-GDTC-003 | B12: Gestión de tareas — Crear | C12: HU-001 / RF-001 / RF-010 | D12: Intentar crear tarea sin título | E12: La aplicación está abierta con el formulario de nueva tarea. | F12: 1 | G12: Dejar el campo título vacío. | H12: Título: '' (vacío) | I12: El campo título aparece vacío; el resto de campos son opcionales. | J12: Alta | K12: Validación | L12: Pendiente
F13: 2 | G13: Intentar guardar sin escribir ningún título. | H13: — | I13: El formulario muestra un error de validación indicando que el título es obligatorio; no se crea la tarea ni se llama a la API.
A14: TC-GDTC-004 | B14: Gestión de tareas — Crear | C14: HU-001 / Reglas de negocio del modelo | D14: Intentar crear tarea con título solo espacios | E14: La aplicación está abierta con el formulario de nueva tarea. | F14: 1 | G14: Escribir únicamente espacios en el campo título. | H14: Título: ' ' | I14: El campo admite la entrada de espacios sin mostrar error inmediato. | J14: Media | K14: Validación | L14: Pendiente
F15: 2 | G15: Intentar guardar la tarea. | H15: — | I15: El formulario rechaza el título por considerarlo vacío (solo espacios); no se crea la tarea.
A16: Gestión de tareas — Editar
A17: TC-GDTE-001 | B17: Gestión de tareas — Editar | C17: HU-002 / RF-002 | D17: Editar todos los campos de una tarea existente | E17: Existe al menos una tarea creada. | F17: 1 | G17: Abrir una tarea existente para editar. | H17: — | I17: El formulario de edición se muestra precargado con los valores actuales de la tarea. | J17: Alta | K17: Funcional | L17: Pendiente
F18: 2 | G18: Cambiar título, descripción, prioridad, categoría, fecha de vencimiento y usuario asignado. | H18: Nuevos valores distintos a los originales en cada campo | I18: Cada campo modificado muestra el nuevo valor introducido sin errores de validación.
F19: 3 | G19: Guardar los cambios. | H19: — | I19: Los cambios se guardan, se reflejan inmediatamente en la lista y persisten tras recargar la página.
A20: TC-GDTE-002 | B20: Gestión de tareas — Editar | C20: HU-002 / RF-010 | D20: Editar tarea dejando el título vacío | E20: Existe al menos una tarea creada. | F20: 1 | G20: Abrir una tarea existente para editar. | H20: — | I20: El formulario muestra el título actual de la tarea. | J20: Alta | K20: Validación | L20: Pendiente
F21: 2 | G21: Borrar completamente el contenido del campo título. | H21: Título: '' (vacío) | I21: El campo título queda vacío.
F22: 3 | G22: Intentar guardar los cambios. | H22: — | I22: El formulario muestra un error de validación y no guarda el cambio; la tarea conserva su título anterior al recargar.
A23: TC-GDTE-003 | B23: Gestión de tareas — Editar | C23: RF-002 | D23: Editar tarea con Id inexistente (acceso directo) | E23: Se conoce un Id de tarea que no existe (por ejemplo, uno ya eliminado). | F23: 1 | G23: Intentar consultar o editar una tarea usando un Id que no existe (por API o navegación directa). | H23: Id inexistente, p. ej. 999999 | I23: La operación no permite cargar datos de una tarea inexistente. | J23: Media | K23: Negativo | L23: Pendiente
F24: 2 | G24: Comprobar la respuesta de la aplicación/API. | H24: — | I24: La API devuelve 404 y la interfaz muestra un mensaje de 'tarea no encontrada' sin romper la aplicación.
A25: Gestión de tareas — Completar y reabrir
A26: TC-GDTC-001 | B26: Gestión de tareas — Completar y reabrir | C26: HU-003 / RF-004 | D26: Marcar una tarea pendiente como completada | E26: Existe una tarea pendiente. | F26: 1 | G26: Localizar una tarea pendiente en la lista. | H26: — | I26: La tarea se muestra con estado pendiente y la acción de completar disponible. | J26: Alta | K26: Funcional | L26: Pendiente
F27: 2 | G27: Marcar la tarea como completada. | H27: — | I27: El estado cambia a completado, la tarea se muestra tachada/con menor contraste y el cambio persiste tras recargar.
A28: TC-GDTC-002 | B28: Gestión de tareas — Completar y reabrir | C28: HU-004 / RF-005 | D28: Reabrir una tarea completada | E28: Existe una tarea completada. | F28: 1 | G28: Localizar una tarea completada. | H28: — | I28: La tarea se muestra tachada/con menor contraste y con la acción de reabrir disponible. | J28: Alta | K28: Funcional | L28: Pendiente
F29: 2 | G29: Reabrir la tarea. | H29: — | I29: El estado vuelve a pendiente, la tarea deja de mostrarse tachada y el cambio persiste tras recargar.
A30: TC-GDTC-003 | B30: Gestión de tareas — Completar y reabrir | C30: HU-003 | D30: Completar una tarea ya completada | E30: Existe una tarea ya marcada como completada. | F30: 1 | G30: Localizar una tarea ya marcada como completada. | H30: — | I30: La tarea se muestra como completada. | J30: Baja | K30: Negativo | L30: Pendiente
F31: 2 | G31: Intentar volver a marcarla como completada. | H31: — | I31: La operación no produce error visible ni duplica el efecto; la tarea permanece completada.
A32: Gestión de tareas — Eliminar
A33: TC-GDTE-001 | B33: Gestión de tareas — Eliminar | C33: HU-005 / RF-003 | D33: Eliminar una tarea con confirmación | E33: Existe al menos una tarea creada. | F33: 1 | G33: Pulsar eliminar sobre una tarea. | H33: — | I33: La aplicación muestra un diálogo de confirmación antes de eliminar. | J33: Alta | K33: Funcional | L33: Pendiente
F34: 2 | G34: Confirmar la eliminación en el diálogo. | H34: — | I34: La tarea desaparece de la lista y de la base de datos; no reaparece al recargar.
A35: TC-GDTE-002 | B35: Gestión de tareas — Eliminar | C35: HU-005 / RF-003 | D35: Cancelar la eliminación de una tarea | E35: Existe al menos una tarea creada. | F35: 1 | G35: Pulsar eliminar sobre una tarea. | H35: — | I35: Se muestra el diálogo de confirmación de eliminación. | J35: Media | K35: Funcional | L35: Pendiente
F36: 2 | G36: Cancelar el diálogo de confirmación. | H36: — | I36: La tarea NO se elimina y sigue visible en la lista tal cual estaba.
A37: TC-GDTE-003 | B37: Gestión de tareas — Eliminar | C37: RF-003 | D37: Eliminar tarea con Id inexistente | E37: Se conoce un Id de tarea que ya no existe. | F37: 1 | G37: Intentar eliminar una tarea con un Id inexistente (vía API o repitiendo el borrado dos veces rápido). | H37: Id inexistente | I37: La operación se envía contra un recurso que ya no existe. | J37: Baja | K37: Negativo | L37: Pendiente
F38: 2 | G38: Comprobar la respuesta. | H38: — | I38: La API devuelve 404 y la interfaz no rompe ni muestra un error genérico no controlado.
A39: Organización — Prioridad, categoría y vencimiento
A40: TC-OPCY-001 | B40: Organización — Prioridad, categoría y vencimiento | C40: Alcance V1 — Organización | D40: Asignar cada nivel de prioridad | E40: Existe al menos una tarea. | F40: 1 | G40: Editar una tarea y asignar prioridad Baja, guardar. | H40: Prioridad: Low | I40: El cambio se guarda y la etiqueta de prioridad Baja se muestra correctamente. | J40: Media | K40: Funcional | L40: Pendiente
F41: 2 | G41: Editar la misma tarea y asignar prioridad Media, guardar. | H41: Prioridad: Medium | I41: El cambio se guarda y la etiqueta de prioridad Media se muestra correctamente.
...
